Exception in Tkinter callback
Traceback (most recent call last):
  File "C:\ProgramData\Anaconda3\lib\tkinter\__init__.py", line 1892, in __call__
    return self.func(*args)
  File "C:\Users\KOSV1106\AppData\Local\Temp\1/ipykernel_2532/4094893807.py", line 130, in <lambda>
    update_button = ttk.Button(info_frame, text="Update Metrics", command=lambda: update_dashboard(server_var.get(), "kosv1106", "c3RM21nvPx2&%32fsp93v"))
  File "C:\Users\KOSV1106\AppData\Local\Temp\1/ipykernel_2532/4094893807.py", line 101, in update_dashboard
    cpu_fig = create_gauge("CPU Usage", cpu_usage, "blue")
  File "C:\Users\KOSV1106\AppData\Local\Temp\1/ipykernel_2532/4094893807.py", line 62, in create_gauge
    return go.Figure(go.Indicator(
  File "C:\ProgramData\Anaconda3\Lib\site-packages\plotly\graph_objects\__init__.py", line 303, in __getattr__
    return orig_getattr(import_name)
  File "C:\ProgramData\Anaconda3\Lib\site-packages\_plotly_utils\importers.py", line 37, in __getattr__
    return getattr(class_module, class_name)
  File "C:\ProgramData\Anaconda3\Lib\site-packages\plotly\graph_objs\__init__.py", line 303, in __getattr__
    return orig_getattr(import_name)
  File "C:\ProgramData\Anaconda3\Lib\site-packages\_plotly_utils\importers.py", line 36, in __getattr__
    class_module = importlib.import_module(rel_module, parent_name)
  File "C:\ProgramData\Anaconda3\lib\importlib\__init__.py", line 127, in import_module
    return _bootstrap._gcd_import(name[level:], package, level)
  File "<frozen importlib._bootstrap>", line 1030, in _gcd_import
  File "<frozen importlib._bootstrap>", line 1007, in _find_and_load
  File "<frozen importlib._bootstrap>", line 986, in _find_and_load_unlocked
  File "<frozen importlib._bootstrap>", line 680, in _load_unlocked
  File "<frozen importlib._bootstrap_external>", line 850, in exec_module
  File "<frozen importlib._bootstrap>", line 228, in _call_with_frames_removed
  File "C:\ProgramData\Anaconda3\Lib\site-packages\plotly\graph_objs\_figure.py", line 1, in <module>
    from plotly.basedatatypes import BaseFigure
  File "C:\ProgramData\Anaconda3\Lib\site-packages\plotly\basedatatypes.py", line 10, in <module>
    from _plotly_utils.utils import (
  File "C:\ProgramData\Anaconda3\Lib\site-packages\_plotly_utils\utils.py", line 9, in <module>
    from _plotly_utils.basevalidators import (
  File "C:\ProgramData\Anaconda3\Lib\site-packages\_plotly_utils\basevalidators.py", line 11, in <module>
    import narwhals.stable.v1 as nw
  File "C:\ProgramData\Anaconda3\Lib\site-packages\narwhals\__init__.py", line 7, in <module>
    from narwhals import stable
  File "C:\ProgramData\Anaconda3\Lib\site-packages\narwhals\stable\__init__.py", line 3, in <module>
    from narwhals.stable import v1
  File "C:\ProgramData\Anaconda3\Lib\site-packages\narwhals\stable\v1\__init__.py", line 24, in <module>
    from narwhals.functions import Then as NwThen
  File "C:\ProgramData\Anaconda3\Lib\site-packages\narwhals\functions.py", line 30, in <module>
    from narwhals.series import Series
  File "C:\ProgramData\Anaconda3\Lib\site-packages\narwhals\series.py", line 22, in <module>
    from narwhals.typing import IntoSeriesT
  File "C:\ProgramData\Anaconda3\Lib\site-packages\narwhals\typing.py", line 10, in <module>
    from narwhals._compliant import CompliantDataFrame
  File "C:\ProgramData\Anaconda3\Lib\site-packages\narwhals\_compliant\__init__.py", line 3, in <module>
    from narwhals._compliant.dataframe import CompliantDataFrame
  File "C:\ProgramData\Anaconda3\Lib\site-packages\narwhals\_compliant\dataframe.py", line 21, in <module>
    from narwhals._translate import ArrowConvertible
  File "C:\ProgramData\Anaconda3\Lib\site-packages\narwhals\_translate.py", line 49, in <module>
    FromNumpyDT_contra = TypeVar(
TypeError: __init__() got an unexpected keyword argument 'default'
â€‹
