Exception in Tkinter callback
Traceback (most recent call last):
  File "C:\ProgramData\Anaconda3\lib\tkinter\__init__.py", line 1892, in __call__
    return self.func(*args)
  File "C:\Users\KOSV1106\AppData\Local\Temp\1/ipykernel_2532/2720086366.py", line 136, in <lambda>
    update_button = tk.Button(root, text="Update Metrics", command=lambda: update_metrics(server_var.get(), username, password))
  File "C:\Users\KOSV1106\AppData\Local\Temp\1/ipykernel_2532/2720086366.py", line 77, in update_metrics
    draw_speedometer(c_drive_usage, c_total_size, c_used_space, c_free_space, ax_c)
  File "C:\Users\KOSV1106\AppData\Local\Temp\1/ipykernel_2532/2720086366.py", line 92, in draw_speedometer
    ax.set_theta_direction(-1)
AttributeError: 'AxesSubplot' object has no attribute 'set_theta_direction'
